Workbook

Sheet VISION GENERAL
A1: REPORTE DEL SERVICIO DE NEFROLOGÍA
E2: Hospital Universitario "Manuel Nuñez Tovar"
E3: Sección 1: Visión General
B6: Indicador | D6: Total | E6: Edad Promedio | F6: Hombres | G6: Mujeres | H6: Variación Período
B7: Pacientes Activos
B8: Pacientes Hipertensos
B9: Pacientes Diabéticos
B11: Distribución de Pacientes Diabéticos:
B12: • Diabetes Tipo 1:
B13: • Diabetes Tipo 2:
E15: Sección 2: Revisión General
B18: Estado | D18: Cantidad | E18: Porcentaje | G18: Tipo | H18: Cantidad | I18: Porcentaje
B19: Crítico | E19: =(D19*100/SUM(D19:D21))/100 -> #DIV/0! | G19: Hemodiálisis | I19: =(H19*100/SUM(H19:H20))/100 -> #DIV/0!
B20: Estable | E20: =(D20*100/SUM(D19:D21))/100 -> #DIV/0! | G20: Peritoneal | I20: =(H20*100/SUM(H19:H20))/100 -> #DIV/0!
B21: Mejorando | E21: =(D21*100/SUM(D19:D21))/100 -> #DIV/0!
B25: Mes | E25: Pacientes | G25: Tipo de AV | H25: Cantidad | I25: Porcentaje
B26: {='DATOS OCULTOS'!I2:J2} -> #VALUE! | E26: ='DATOS OCULTOS'!K2 -> 0 | G26: Catéter Peritoneal | H26: ='DATOS OCULTOS'!C16 -> 0 | I26: =(H26*100/SUM(H26:H28))/100 -> #DIV/0!
B27: {='DATOS OCULTOS'!I3:J3} -> #VALUE! | E27: ='DATOS OCULTOS'!K3 -> 0 | G27: Catéter Temporal | H27: ='DATOS OCULTOS'!C17 -> 0 | I27: =(H27*100/SUM(H26:H28))/100 -> #DIV/0!
B28: {='DATOS OCULTOS'!I4:J4} -> #VALUE! | E28: ='DATOS OCULTOS'!K4 -> 0 | G28: Fistula VA | H28: ='DATOS OCULTOS'!C18 -> 0 | I28: =(H28*100/SUM(H26:H28))/100 -> #DIV/0!
E34: Sección 3: Distribución Demográfica
B41: Grupo Edad | D41: Cantidad | E41: Porcentaje | G41: Sexo | H41: Cantidad | I41: Porcentaje
B42: 0-18 | D42: ='DATOS OCULTOS'!B5 -> 0 | E42: =(D42*100/SUM(D42:D45))/100 -> #DIV/0! | G42: Hombre | H42: ='DATOS OCULTOS'!F5 -> 0 | I42: =(H42*100/SUM(H42:H43))/100 -> #DIV/0!
B43: 19-30 | D43: ='DATOS OCULTOS'!B6 -> 0 | E43: =(D43*100/SUM(D42:D45))/100 -> #DIV/0! | G43: Mujer | H43: ='DATOS OCULTOS'!F6 -> 0 | I43: =(H43*100/SUM(H42:H43))/100 -> #DIV/0!
B44: 31-45 | D44: ='DATOS OCULTOS'!B7 -> 0 | E44: =(D44*100/SUM(D42:D45))/100 -> #DIV/0!
B45: 46-60 | D45: ='DATOS OCULTOS'!B8 -> 0 | E45: =(D45*100/SUM(D42:D45))/100 -> #DIV/0!
D53: Etnia | F53: Cantidad | G53: Porcentaje
D54: Caucásico | G54: =(F54*100/SUM(F54:F56))/100 -> #DIV/0!
D55: Afro | G55: =(F55*100/SUM(F54:F56))/100 -> #DIV/0!
D56: Asiático | G56: =(F56*100/SUM(F54:F56))/100 -> #DIV/0!
E60: Sección 4: Distribución Clínica
B64: Hemoglobina | G64: Hematocrito
B65: ='DATOS OCULTOS'!C21 -> 12.0 - 16.0 g/dL | D65: ="Promedio: "&'DATOS OCULTOS'!B21&" g/dL" -> Promedio: g/dL | G65: ='DATOS OCULTOS'!G21 -> 36% - 48% | H65: ="Promedio: "&'DATOS OCULTOS'!F21&"%" -> Promedio: %
B66: Mes | D66: Valor | G66: Mes | H66: Valor
B67: ='DATOS OCULTOS'!B22 -> Formato Inválido | D67: ='DATOS OCULTOS'!C22&" g/dL" -> g/dL | G67: ='DATOS OCULTOS'!F22 -> Formato Inválido | H67: ='DATOS OCULTOS'!G22&"%" -> %
B68: ='DATOS OCULTOS'!B23 -> Formato Inválido | D68: ='DATOS OCULTOS'!C23&" g/dL" -> g/dL | G68: ='DATOS OCULTOS'!F23 -> Formato Inválido | H68: ='DATOS OCULTOS'!G23&"%" -> %
B69: ='DATOS OCULTOS'!B24 -> Formato Inválido | D69: ='DATOS OCULTOS'!C24&" g/dL" -> g/dL | G69: ='DATOS OCULTOS'!F24 -> Formato Inválido | H69: ='DATOS OCULTOS'!G24&"%" -> %
B75: Glicemia | G75: Urea
B76: ='DATOS OCULTOS'!K21 -> 70 - 100 mg/dL | D76: ="Promedio: "&'DATOS OCULTOS'!J21&" mg/dL" -> Promedio: mg/dL | G76: ='DATOS OCULTOS'!O21 -> 10 - 50 mg/dL | H76: ="Promedio: "&'DATOS OCULTOS'!N21&" mg/dL" -> Promedio: mg/dL
B77: Mes | D77: Valor | G77: Mes | H77: Valor
B78: ='DATOS OCULTOS'!J22 -> Formato Inválido | D78: ='DATOS OCULTOS'!K22&" mg/dL" -> mg/dL | G78: ='DATOS OCULTOS'!N22 -> Formato Inválido | H78: ='DATOS OCULTOS'!O22&" mg/dL" -> mg/dL
...

Sheet DATOS OCULTOS
A1: DISTRIBUCIÓN DEMOGRÁFICA | I1: Mes | K1: Pacientes
A3: Distribución por Grupos de Edad | E3: Distribución por Sexo
A4: Grupo Edad | B4: Cantidad | C4: Porcentaje | E4: Sexo | F4: Cantidad | G4: Porcentaje
A5: 0-18 | C5: 1.3% | E5: Hombre | G5: 32.5%
A6: 19-30 | C6: 5.0% | E6: Mujer | G6: 20.0%
A7: 31-45 | C7: 2.5%
A8: 46-60 | C8: 1.3%
A10: Etnia | B10: Porcentaje | C10: Cantidad
A11: Caucásico | B11: 23.8%
A12: Afro | B12: 13.8%
A13: Asiático | B13: 7.5%
A15: Tipo de Acceso Vascular | C15: Cantidad
A16: Catéter Peritoneal
A17: Catéter Temporal
A18: Fistula VA
A21: HEMOGLOBINA | C21: 12.0 - 16.0 g/dL | E21: HEMATOCRITO | G21: 36% - 48% | I21: GLICEMIA | K21: 70 - 100 mg/dL | M21: UREA | O21: 10 - 50 mg/dL | Q21: CREATININA | S21: 0.6 - 1.2 mg/dL | U21: ALBUMINA | W21: 3.4 - 5.4 g/dL | Y21: CALCIO | AA21: 8.5 - 10.5 mg/dL | AC21: FOSFORO | AE21: 2.5 - 4.5 mg/dL
B22: =PROPER(IF(OR(A22="",ISERROR(DATE(LEFT(A22,4),RIGHT(A22,2),1))),"Formato inválido",TEXT(DATE(LEFT(A22,4),RIGHT(A22,2),1),"mmmm")&" "&LEFT(A22,4))) -> Formato Inválido | F22: =PROPER(IF(OR(E22="",ISERROR(DATE(LEFT(E22,4),RIGHT(E22,2),1))),"Formato inválido",TEXT(DATE(LEFT(E22,4),RIGHT(E22,2),1),"mmmm")&" "&LEFT(E22,4))) -> Formato Inválido | J22: =PROPER(IF(OR(I22="",ISERROR(DATE(LEFT(I22,4),RIGHT(I22,2),1))),"Formato inválido",TEXT(DATE(LEFT(I22,4),RIGHT(I22,2),1),"mmmm")&" "&LEFT(I22,4))) -> Formato Inválido | N22: =PROPER(IF(OR(M22="",ISERROR(DATE(LEFT(M22,4),RIGHT(M22,2),1))),"Formato inválido",TEXT(DATE(LEFT(M22,4),RIGHT(M22,2),1),"mmmm")&" "&LEFT(M22,4))) -> Formato Inválido | R22: =PROPER(IF(OR(Q22="",ISERROR(DATE(LEFT(Q22,4),RIGHT(Q22,2),1))),"Formato inválido",TEXT(DATE(LEFT(Q22,4),RIGHT(Q22,2),1),"mmmm")&" "&LEFT(Q22,4))) -> Formato Inválido | V22: =PROPER(IF(OR(U22="",ISERROR(DATE(LEFT(U22,4),RIGHT(U22,2),1))),"Formato inválido",TEXT(DATE(LEFT(U22,4),RIGHT(U22,2),1),"mmmm")&" "&LEFT(U22,4))) -> Formato Inválido | Z22: =PROPER(IF(OR(Y22="",ISERROR(DATE(LEFT(Y22,4),RIGHT(Y22,2),1))),"Formato inválido",TEXT(DATE(LEFT(Y22,4),RIGHT(Y22,2),1),"mmmm")&" "&LEFT(Y22,4))) -> Formato Inválido | AD22: =PROPER(IF(OR(AC22="",ISERROR(DATE(LEFT(AC22,4),RIGHT(AC22,2),1))),"Formato inválido",TEXT(DATE(LEFT(AC22,4),RIGHT(AC22,2),1),"mmmm")&" "&LEFT(AC22,4))) -> Formato Inválido
B23: =PROPER(IF(OR(A23="",ISERROR(DATE(LEFT(A23,4),RIGHT(A23,2),1))),"Formato inválido",TEXT(DATE(LEFT(A23,4),RIGHT(A23,2),1),"mmmm")&" "&LEFT(A23,4))) -> Formato Inválido | F23: =PROPER(IF(OR(E23="",ISERROR(DATE(LEFT(E23,4),RIGHT(E23,2),1))),"Formato inválido",TEXT(DATE(LEFT(E23,4),RIGHT(E23,2),1),"mmmm")&" "&LEFT(E23,4))) -> Formato Inválido | J23: =PROPER(IF(OR(I23="",ISERROR(DATE(LEFT(I23,4),RIGHT(I23,2),1))),"Formato inválido",TEXT(DATE(LEFT(I23,4),RIGHT(I23,2),1),"mmmm")&" "&LEFT(I23,4))) -> Formato Inválido | N23: =PROPER(IF(OR(M23="",ISERROR(DATE(LEFT(M23,4),RIGHT(M23,2),1))),"Formato inválido",TEXT(DATE(LEFT(M23,4),RIGHT(M23,2),1),"mmmm")&" "&LEFT(M23,4))) -> Formato Inválido | R23: =PROPER(IF(OR(Q23="",ISERROR(DATE(LEFT(Q23,4),RIGHT(Q23,2),1))),"Formato inválido",TEXT(DATE(LEFT(Q23,4),RIGHT(Q23,2),1),"mmmm")&" "&LEFT(Q23,4))) -> Formato Inválido | V23: =PROPER(IF(OR(U23="",ISERROR(DATE(LEFT(U23,4),RIGHT(U23,2),1))),"Formato inválido",TEXT(DATE(LEFT(U23,4),RIGHT(U23,2),1),"mmmm")&" "&LEFT(U23,4))) -> Formato Inválido | Z23: =PROPER(IF(OR(Y23="",ISERROR(DATE(LEFT(Y23,4),RIGHT(Y23,2),1))),"Formato inválido",TEXT(DATE(LEFT(Y23,4),RIGHT(Y23,2),1),"mmmm")&" "&LEFT(Y23,4))) -> Formato Inválido | AD23: =PROPER(IF(OR(AC23="",ISERROR(DATE(LEFT(AC23,4),RIGHT(AC23,2),1))),"Formato inválido",TEXT(DATE(LEFT(AC23,4),RIGHT(AC23,2),1),"mmmm")&" "&LEFT(AC23,4))) -> Formato Inválido
B24: =PROPER(IF(OR(A24="",ISERROR(DATE(LEFT(A24,4),RIGHT(A24,2),1))),"Formato inválido",TEXT(DATE(LEFT(A24,4),RIGHT(A24,2),1),"mmmm")&" "&LEFT(A24,4))) -> Formato Inválido | F24: =PROPER(IF(OR(E24="",ISERROR(DATE(LEFT(E24,4),RIGHT(E24,2),1))),"Formato inválido",TEXT(DATE(LEFT(E24,4),RIGHT(E24,2),1),"mmmm")&" "&LEFT(E24,4))) -> Formato Inválido | J24: =PROPER(IF(OR(I24="",ISERROR(DATE(LEFT(I24,4),RIGHT(I24,2),1))),"Formato inválido",TEXT(DATE(LEFT(I24,4),RIGHT(I24,2),1),"mmmm")&" "&LEFT(I24,4))) -> Formato Inválido | N24: =PROPER(IF(OR(M24="",ISERROR(DATE(LEFT(M24,4),RIGHT(M24,2),1))),"Formato inválido",TEXT(DATE(LEFT(M24,4),RIGHT(M24,2),1),"mmmm")&" "&LEFT(M24,4))) -> Formato Inválido | R24: =PROPER(IF(OR(Q24="",ISERROR(DATE(LEFT(Q24,4),RIGHT(Q24,2),1))),"Formato inválido",TEXT(DATE(LEFT(Q24,4),RIGHT(Q24,2),1),"mmmm")&" "&LEFT(Q24,4))) -> Formato Inválido | V24: =PROPER(IF(OR(U24="",ISERROR(DATE(LEFT(U24,4),RIGHT(U24,2),1))),"Formato inválido",TEXT(DATE(LEFT(U24,4),RIGHT(U24,2),1),"mmmm")&" "&LEFT(U24,4))) -> Formato Inválido | Z24: =PROPER(IF(OR(Y24="",ISERROR(DATE(LEFT(Y24,4),RIGHT(Y24,2),1))),"Formato inválido",TEXT(DATE(LEFT(Y24,4),RIGHT(Y24,2),1),"mmmm")&" "&LEFT(Y24,4))) -> Formato Inválido | AD24: =PROPER(IF(OR(AC24="",ISERROR(DATE(LEFT(AC24,4),RIGHT(AC24,2),1))),"Formato inválido",TEXT(DATE(LEFT(AC24,4),RIGHT(AC24,2),1),"mmmm")&" "&LEFT(AC24,4))) -> Formato Inválido
